{"uuid": "1b4481fb-1807-433a-9e02-c2de52ead0be", "children": ["4bf1bf47-c39f-4526-9376-cdbd11945758"], "befores": [{"name": "_Class__pytest_setup_method", "status": "broken", "statusDetails": {"message": "selenium.common.exceptions.WebDriverException: Message: unknown error: Chrome failed to start: exited normally.\n  (chrome not reachable)\n  (The process started from chrome location C:\\Program Files (x86)\\Google\\Chrome\\Application\\chrome.exe is no longer running, so ChromeDriver is assuming that Chrome has crashed.)\n\n", "trace": "  File \"C:\\ProgramData\\Anaconda3\\lib\\site-packages\\pluggy\\callers.py\", line 187, in _multicall\n    res = hook_impl.function(*args)\n  File \"C:\\ProgramData\\Anaconda3\\lib\\site-packages\\_pytest\\fixtures.py\", line 923, in pytest_fixture_setup\n    result = call_fixture_func(fixturefunc, request, kwargs)\n  File \"C:\\ProgramData\\Anaconda3\\lib\\site-packages\\_pytest\\fixtures.py\", line 779, in call_fixture_func\n    res = next(it)\n  File \"C:\\ProgramData\\Anaconda3\\lib\\site-packages\\_pytest\\python.py\", line 772, in xunit_setup_method_fixture\n    _call_with_optional_argument(func, method)\n  File \"C:\\ProgramData\\Anaconda3\\lib\\site-packages\\_pytest\\python.py\", line 686, in _call_with_optional_argument\n    func(arg)\n  File \"D:\\github\\jobpool\\python_learning\\test\\baidu\\test_searchpython.py\", line 15, in setup_method\n    self.driver = webdriver.Chrome()\n  File \"C:\\ProgramData\\Anaconda3\\lib\\site-packages\\selenium\\webdriver\\chrome\\webdriver.py\", line 81, in __init__\n    desired_capabilities=desired_capabilities)\n  File \"C:\\ProgramData\\Anaconda3\\lib\\site-packages\\selenium\\webdriver\\remote\\webdriver.py\", line 157, in __init__\n    self.start_session(capabilities, browser_profile)\n  File \"C:\\ProgramData\\Anaconda3\\lib\\site-packages\\selenium\\webdriver\\remote\\webdriver.py\", line 252, in start_session\n    response = self.execute(Command.NEW_SESSION, parameters)\n  File \"C:\\ProgramData\\Anaconda3\\lib\\site-packages\\selenium\\webdriver\\remote\\webdriver.py\", line 321, in execute\n    self.error_handler.check_response(response)\n  File \"C:\\ProgramData\\Anaconda3\\lib\\site-packages\\selenium\\webdriver\\remote\\errorhandler.py\", line 242, in check_response\n    raise exception_class(message, screen, stacktrace)\n"}, "start": 1599269306852, "stop": 1599269324460}], "start": 1599269306852, "stop": 1599269324618}